mplus_output/uni-08-HRS_W8.out
Mplus VERSION 8.1 (Mac)
MUTHEN & MUTHEN
04/23/2020  10:56 PM

INPUT INSTRUCTIONS

  DATA:
  FILE = "uni-08-HRS_W8.dat";

  VARIABLE:
  NAMES = mplusid UDAT UDAY UMON UYER UIWR UDWR USUB UBAK UNM1 UNM2 UNM5 UNM6 URE3
       URE5 URE6;
   MISSING=.;
   CATEGORICAL ARE all; idvariable = mplusid;
  ANALYSIS:
  estimator = wlsmv; coverage=0;
  MODEL:
  g by UDAT * ;
   g by UDAY * ;
   g by UMON * ;
   g by UYER * ;
   g by UIWR * ;
   g by UDWR * ;
   g by USUB * ;
   g by UBAK * ;
   g by UNM1 * ;
   g by UNM2 * ;
   g by UNM5 * ;
   g by UNM6 * ;
   g by URE3 * ;
   g by URE5 * ;
   g by URE6 * ;
   g @ 1;

  OUTPUT:
  standardized; svalues;



*** WARNING
  Data set contains cases with missing on all variables.
  These cases were not included in the analysis.
  Number of cases with missing on all variables:  2038
   1 WARNING(S) FOUND IN THE INPUT INSTRUCTIONS




SUMMARY OF ANALYSIS

Number of groups                                                 1
Number of observations                                       16129

Number of dependent variables                                   15
Number of independent variables                                  0
Number of continuous latent variables                            1

Observed dependent variables

  Binary and ordered categorical (ordinal)
   UDAT        UDAY        UMON        UYER        UIWR        UDWR
   USUB        UBAK        UNM1        UNM2        UNM5        UNM6
   URE3        URE5        URE6

Continuous latent variables
   G

Variables with special functions

  ID variable           MPLUSID

Estimator                                                    WLSMV
Maximum number of iterations                                  1000
Convergence criterion                                    0.500D-04
Maximum number of steepest descent iterations                   20
Maximum number of iterations for H1                           2000
Convergence criterion for H1                             0.100D-03
Parameterization                                             DELTA
Link                                                        PROBIT

Input data file(s)
  uni-08-HRS_W8.dat

Input data format  FREE


SUMMARY OF DATA

     Number of missing data patterns           270


COVARIANCE COVERAGE OF DATA

Minimum covariance coverage value   0.000


     PROPORTION OF DATA PRESENT


           Covariance Coverage
              UDAT          UDAY          UMON          UYER          UIWR
              ________      ________      ________      ________      ________
 UDAT           0.588
 UDAY           0.587         0.592
 UMON           0.587         0.590         0.591
 UYER           0.587         0.591         0.590         0.592
 UIWR           0.581         0.585         0.585         0.585         0.990
 UDWR           0.579         0.583         0.582         0.582         0.987
 USUB           0.533         0.536         0.536         0.536         0.914
 UBAK           0.581         0.586         0.585         0.585         0.985
 UNM1           0.586         0.591         0.590         0.590         0.587
 UNM2           0.566         0.569         0.569         0.569         0.566
 UNM5           0.579         0.583         0.583         0.583         0.579
 UNM6           0.512         0.514         0.514         0.514         0.511
 URE3           0.588         0.592         0.591         0.592         0.887
 URE5           0.439         0.441         0.440         0.441         0.672
 URE6           0.419         0.421         0.421         0.421         0.651


           Covariance Coverage
              UDWR          USUB          UBAK          UNM1          UNM2
              ________      ________      ________      ________      ________
 UDWR           0.987
 USUB           0.912         0.918
 UBAK           0.982         0.917         0.991
 UNM1           0.585         0.538         0.588         0.594
 UNM2           0.564         0.524         0.566         0.571         0.572
 UNM5           0.577         0.533         0.580         0.585         0.565
 UNM6           0.509         0.478         0.511         0.515         0.505
 URE3           0.884         0.820         0.888         0.594         0.572
 URE5           0.671         0.661         0.674         0.441         0.433
 URE6           0.650         0.642         0.653         0.422         0.415


           Covariance Coverage
              UNM5          UNM6          URE3          URE5          URE6
              ________      ________      ________      ________      ________
 UNM5           0.586
 UNM6           0.515         0.516
 URE3           0.586         0.516         0.897
 URE5           0.438         0.399         0.675         0.675
 URE6           0.419         0.385         0.655         0.575         0.655


UNIVARIATE PROPORTIONS AND COUNTS FOR CATEGORICAL VARIABLES

    UDAT
      Category 1    0.155         1467.000
      Category 2    0.845         8013.000
    UDAY
      Category 1    0.040          381.000
      Category 2    0.960         9172.000
    UMON
      Category 1    0.030          284.000
      Category 2    0.970         9255.000
    UYER
      Category 1    0.038          364.000
      Category 2    0.962         9179.000
    UIWR
      Category 1    0.015          244.000
      Category 2    0.008          130.000
      Category 3    0.030          487.000
      Category 4    0.079         1266.000
      Category 5    0.154         2459.000
      Category 6    0.441         7047.000
      Category 7    0.155         2473.000
      Category 8    0.078         1248.000
      Category 9    0.028          455.000
      Category 10    0.010          164.000
    UDWR
      Category 1    0.071         1134.000
      Category 2    0.033          529.000
      Category 3    0.071         1134.000
      Category 4    0.131         2088.000
      Category 5    0.185         2945.000
      Category 6    0.349         5557.000
      Category 7    0.091         1441.000
      Category 8    0.043          688.000
      Category 9    0.017          277.000
      Category 10    0.008          129.000
    USUB
      Category 1    0.039          582.000
      Category 2    0.099         1465.000
      Category 3    0.079         1171.000
      Category 4    0.123         1821.000
      Category 5    0.186         2762.000
      Category 6    0.473         7009.000
    UBAK
      Category 1    0.043          684.000
      Category 2    0.957        15301.000
    UNM1
      Category 1    0.009           86.000
      Category 2    0.991         9498.000
    UNM2
      Category 1    0.059          542.000
      Category 2    0.941         8682.000
    UNM5
      Category 1    0.027          256.000
      Category 2    0.973         9193.000
    UNM6
      Category 1    0.207         1722.000
      Category 2    0.793         6598.000
    URE3
      Category 1    0.319         4609.000
      Category 2    0.681         9857.000
    URE5
      Category 1    0.459         4997.000
      Category 2    0.541         5895.000
    URE6
      Category 1    0.452         4769.000
      Category 2    0.445         4700.000
      Category 3    0.103         1088.000



THE MODEL ESTIMATION TERMINATED NORMALLY



MODEL FIT INFORMATION

Number of Free Parameters                       51

Chi-Square Test of Model Fit

          Value                           5612.615*
          Degrees of Freedom                    90
          P-Value                           0.0000

*   The chi-square value for MLM, MLMV, MLR, ULSMV, WLSM and WLSMV cannot be used
    for chi-square difference testing in the regular way.  MLM, MLR and WLSM
    chi-square difference testing is described on the Mplus website.  MLMV, WLSMV,
    and ULSMV difference testing is done using the DIFFTEST option.

RMSEA (Root Mean Square Error Of Approximation)

          Estimate                           0.062
          90 Percent C.I.                    0.060  0.063
