mplus_output/uni-09-HRS_W9.out
Mplus VERSION 8.1 (Mac)
MUTHEN & MUTHEN
04/23/2020  10:56 PM

INPUT INSTRUCTIONS

  DATA:
  FILE = "uni-09-HRS_W9.dat";

  VARIABLE:
  NAMES = mplusid UDAT UDAY UMON UYER UIWR UDWR USUB UBAK UNM1 UNM2 UNM5 UNM6 URE3
       URE5 URE6;
   MISSING=.;
   CATEGORICAL ARE all; idvariable = mplusid;
  ANALYSIS:
  estimator = wlsmv; coverage=0;
  MODEL:
  g by UDAT * ;
   g by UDAY * ;
   g by UMON * ;
   g by UYER * ;
   g by UIWR * ;
   g by UDWR * ;
   g by USUB * ;
   g by UBAK * ;
   g by UNM1 * ;
   g by UNM2 * ;
   g by UNM5 * ;
   g by UNM6 * ;
   g by URE3 * ;
   g by URE5 * ;
   g by URE6 * ;
   g @ 1;

  OUTPUT:
  standardized; svalues;



*** WARNING
  Data set contains cases with missing on all variables.
  These cases were not included in the analysis.
  Number of cases with missing on all variables:  1859
   1 WARNING(S) FOUND IN THE INPUT INSTRUCTIONS




SUMMARY OF ANALYSIS

Number of groups                                                 1
Number of observations                                       18270

Number of dependent variables                                   15
Number of independent variables                                  0
Number of continuous latent variables                            1

Observed dependent variables

  Binary and ordered categorical (ordinal)
   UDAT        UDAY        UMON        UYER        UIWR        UDWR
   USUB        UBAK        UNM1        UNM2        UNM5        UNM6
   URE3        URE5        URE6

Continuous latent variables
   G

Variables with special functions

  ID variable           MPLUSID

Estimator                                                    WLSMV
Maximum number of iterations                                  1000
Convergence criterion                                    0.500D-04
Maximum number of steepest descent iterations                   20
Maximum number of iterations for H1                           2000
Convergence criterion for H1                             0.100D-03
Parameterization                                             DELTA
Link                                                        PROBIT

Input data file(s)
  uni-09-HRS_W9.dat

Input data format  FREE


SUMMARY OF DATA

     Number of missing data patterns           246


COVARIANCE COVERAGE OF DATA

Minimum covariance coverage value   0.000


     PROPORTION OF DATA PRESENT


           Covariance Coverage
              UDAT          UDAY          UMON          UYER          UIWR
              ________      ________      ________      ________      ________
 UDAT           0.706
 UDAY           0.705         0.712
 UMON           0.705         0.710         0.711
 UYER           0.705         0.710         0.709         0.711
 UIWR           0.700         0.706         0.704         0.705         0.993
 UDWR           0.694         0.700         0.699         0.699         0.985
 USUB           0.655         0.659         0.658         0.658         0.925
 UBAK           0.701         0.707         0.705         0.706         0.715
 UNM1           0.705         0.711         0.710         0.710         0.707
 UNM2           0.685         0.689         0.688         0.689         0.685
 UNM5           0.700         0.705         0.704         0.705         0.701
 UNM6           0.637         0.640         0.639         0.640         0.635
 URE3           0.177         0.178         0.178         0.178         0.178
 URE5           0.154         0.154         0.154         0.154         0.154
 URE6           0.139         0.140         0.140         0.140         0.140


           Covariance Coverage
              UDWR          USUB          UBAK          UNM1          UNM2
              ________      ________      ________      ________      ________
 UDWR           0.985
 USUB           0.922         0.929
 UBAK           0.709         0.667         0.719
 UNM1           0.701         0.660         0.708         0.714
 UNM2           0.680         0.645         0.687         0.691         0.691
 UNM5           0.695         0.656         0.702         0.706         0.686
 UNM6           0.631         0.602         0.637         0.640         0.629
 URE3           0.177         0.171         0.178         0.178         0.175
 URE5           0.154         0.152         0.154         0.154         0.153
 URE6           0.139         0.139         0.140         0.140         0.139


           Covariance Coverage
              UNM5          UNM6          URE3          URE5          URE6
              ________      ________      ________      ________      ________
 UNM5           0.707
 UNM6           0.640         0.641
 URE3           0.177         0.160         0.178
 URE5           0.154         0.143         0.154         0.154
 URE6           0.140         0.132         0.140         0.132         0.140


UNIVARIATE PROPORTIONS AND COUNTS FOR CATEGORICAL VARIABLES

    UDAT
      Category 1    0.163         2108.000
      Category 2    0.837        10789.000
    UDAY
      Category 1    0.037          481.000
      Category 2    0.963        12530.000
    UMON
      Category 1    0.028          368.000
      Category 2    0.972        12618.000
    UYER
      Category 1    0.027          353.000
      Category 2    0.973        12639.000
    UIWR
      Category 1    0.009          156.000
      Category 2    0.008          145.000
      Category 3    0.026          468.000
      Category 4    0.077         1405.000
      Category 5    0.156         2824.000
      Category 6    0.468         8486.000
      Category 7    0.162         2933.000
      Category 8    0.069         1259.000
      Category 9    0.019          353.000
      Category 10    0.006          105.000
    UDWR
      Category 1    0.056         1014.000
      Category 2    0.035          635.000
      Category 3    0.075         1342.000
      Category 4    0.138         2491.000
      Category 5    0.197         3552.000
      Category 6    0.369         6652.000
      Category 7    0.080         1439.000
      Category 8    0.033          589.000
      Category 9    0.012          216.000
      Category 10    0.004           75.000
    USUB
      Category 1    0.036          618.000
      Category 2    0.094         1592.000
      Category 3    0.081         1369.000
      Category 4    0.131         2223.000
      Category 5    0.203         3443.000
      Category 6    0.455         7731.000
    UBAK
      Category 1    0.067          882.000
      Category 2    0.933        12262.000
    UNM1
      Category 1    0.009          112.000
      Category 2    0.991        12933.000
    UNM2
      Category 1    0.054          681.000
      Category 2    0.946        11949.000
    UNM5
      Category 1    0.017          217.000
      Category 2    0.983        12702.000
    UNM6
      Category 1    0.149         1745.000
      Category 2    0.851         9961.000
    URE3
      Category 1    0.219          714.000
      Category 2    0.781         2547.000
    URE5
      Category 1    0.427         1206.000
      Category 2    0.573         1616.000
    URE6
      Category 1    0.403         1031.000
      Category 2    0.449         1148.000
      Category 3    0.148          379.000


     WARNING:  THE BIVARIATE TABLE OF URE5 AND UNM5 HAS AN EMPTY CELL.

     WARNING:  THE SAMPLE CORRELATION OF URE6 AND UNM5 IS  0.986
     DUE TO ONE OR MORE ZERO CELLS IN THEIR BIVARIATE TABLE.
     INFORMATION FROM THESE VARIABLES CAN BE USED TO CREATE ONE NEW VARIABLE.


THE MODEL ESTIMATION TERMINATED NORMALLY



MODEL FIT INFORMATION

Number of Free Parameters                       51

Chi-Square Test of Model Fit

          Value                           4491.050*
          Degrees of Freedom                    90
          P-Value                           0.0000

*   The chi-square value for MLM, MLMV, MLR, ULSMV, WLSM and WLSMV cannot be used
    for chi-square difference testing in the regular way.  MLM, MLR and WLSM
    chi-square difference testing is described on the Mplus website.  MLMV, WLSMV,
